File: testdata_diff_lenghts.txt
Data Series Information
Name:			lm3_s1_sw1 2
Number of Intervals:			1
Application:			RHEOPLUS/32 V3.62 21006865-33024
Device:			MCR302 SN81338429; FW3.71; Slot(8,-1); Adj(1,0)d
Measuring Date/Time:			16/03/2022; 10:36 PM
Measuring System:			PP08-SN84133; [d=0.65 mm]
Accessories:			TU1=P-PTD200-SN81341740

Calculating Constants:
- Norm. Csr [min/s]:			0.41889996
- Norm. Css [Pa/mNm]:			9,945.692
- Start Delay Time [s]:			8.18
- Substance Density [rho]:			1,000
- Measurement Type:			1
- Axial Compliance [m/N]:			1E-6
- Position [m]:			1E-6

Interval:			1
Number of Data Points:			13

Time Setting:			16 Meas. Pts.
Measuring Profile:
- Strain			Amplitude gamma = 0.01 ... 10 % log; |Slope| = 5 Pt. / dec
			Angular Frequency omega = 10 rad/s

Meas. Pts.	Strain	Shear Stress	Angular Frequency	Storage Modulus	Loss Modulus	Damping Factor	Deflection Angle	Torque	Status	Time	Shear Stress	Strain	Normal Force
	[%]	[Pa]	[rad/s]	[Pa]	[Pa]	[1]	[mrad]	[µNm]	[]	[s]	[Pa]	[%]	[N]
1	0.01	8.7E-2	10	8.44E+2	2.12E+2	0.251	0.0162	0.00875	DSO	10.3	0.087	0.01	0.0425
2	0.0159	1.7E-1	10	1.07E+3	1.2E+2	0.112	0.0258	0.0171	DSO	21.2	0.17	0.0159	0.0413
3	0.0251	2.89E-1	10	1.15E+3	5.17E+1	0.0449	0.0408	0.0291	DSO	32.1	0.289	0.0251	0.0414
4	0.0398	4.95E-1	10	1.24E+3	7.97E+1	0.0643	0.0647	0.0498	DSO	43.1	0.495	0.0398	0.041
5	0.0631	7.84E-1	10	1.24E+3	6.57E+1	0.053	0.103	0.0788	DSO	54	0.784	0.0631	0.0407
6	0.1	1.25E0	10	1.25E+3	7.19E+1	0.0578	0.162	0.125	DSO	64.8	1.25	0.1	0.0405
7	0.159	1.95E0	10	1.23E+3	6.98E+1	0.0568	0.258	0.196	DSO	75.8	1.95	0.159	0.0406
8	0.251	3.06E0	10	1.21E+3	7E+1	0.0577	0.408	0.307	DSO	86.7	3.06	0.251	0.0399
9	0.398	4.73E0	10	1.19E+3	7.1E+1	0.0599	0.647	0.476	DSO	97.5	4.73	0.398	0.0397
10	0.631	7.13E0	10	1.13E+3	8.65E+1	0.0768	1.03	0.717	DSO	108	7.13	0.631	0.0394
11	1	1.08E+1	10	1.07E+3	1.04E+2	0.0966	1.62	1.08	DSO	119	10.8	1	0.039
12	1.58	1.64E+1	10	1.03E+3	1.26E+2	0.123	2.58	1.65	DSO	130	16.4	1.58	0.0385
13	2.51	2.48E+1	10	9.74E+2	1.52E+2	0.156	4.08	2.49	DSO	141	24.8	2.51	0.0388

Data Series Information
Name:			lm3_s2_sw 1
Number of Intervals:			1
Application:			RHEOPLUS/32 V3.62 21006865-33024
Device:			MCR302 SN81338429; FW3.71; Slot(8,-1); Adj(1,0)d
Measuring Date/Time:			16/03/2022; 12:08 PM
Measuring System:			PP08-SN84133; [d=0.65 mm]
Accessories:			TU1=P-PTD200-SN81341740

Calculating Constants:
- Norm. Csr [min/s]:			0.41889996
- Norm. Css [Pa/mNm]:			9,945.692
- Start Delay Time [s]:			7.218
- Substance Density [rho]:			1,000
- Measurement Type:			1
- Axial Compliance [m/N]:			1E-6
- Position [m]:			1E-6

Interval:			1
Number of Data Points:			13

Time Setting:			16 Meas. Pts.
Measuring Profile:
- Strain			Amplitude gamma = 0.01 ... 10 % log; |Slope| = 5 Pt. / dec
			Angular Frequency omega = 10 rad/s

Meas. Pts.	Strain	Shear Stress	Angular Frequency	Storage Modulus	Loss Modulus	Damping Factor	Deflection Angle	Torque	Status	Time	Shear Stress	Strain	Normal Force
	[%]	[Pa]	[rad/s]	[Pa]	[Pa]	[1]	[mrad]	[µNm]	[]	[s]	[Pa]	[%]	[N]
1	0.01	1.07E-1	10	1.07E+3	3.43E+1	0.0321	0.0162	0.0107	DSO	10.2	0.107	0.01	0.0434
2	0.0158	1.89E-1	10	1.19E+3	6.42E+1	0.0538	0.0258	0.0191	DSO	21.2	0.189	0.0158	0.0422
3	0.0251	2.83E-1	10	1.12E+3	7.61E+1	0.0677	0.0408	0.0284	DSO	32.1	0.283	0.0251	0.0408
4	0.0398	4.3E-1	10	1.08E+3	4.84E+1	0.0449	0.0647	0.0432	DSO	42.9	0.43	0.0398	0.0402
5	0.0631	6.92E-1	10	1.09E+3	7.57E+1	0.0691	0.103	0.0696	DSO	53.8	0.692	0.0631	0.0396
6	0.1	1.09E0	10	1.09E+3	6.79E+1	0.0623	0.162	0.11	DSO	64.7	1.09	0.1	0.0389
7	0.158	1.7E0	10	1.07E+3	8.09E+1	0.0757	0.258	0.171	DSO	75.5	1.7	0.158	0.0381
8	0.251	2.56E0	10	1.02E+3	8.56E+1	0.0842	0.408	0.258	DSO	86.5	2.56	0.251	0.0376
9	0.398	3.86E0	10	9.64E+2	9.42E+1	0.0978	0.647	0.388	DSO	97.4	3.86	0.398	0.0371
10	0.631	6.32E0	10	9.96E+2	1.05E+2	0.106	1.03	0.635	DSO	108	6.32	0.631	0.0368
11	1	1.12E+1	10	1.11E+3	1.23E+2	0.11	1.63	1.13	DSO	119	11.2	1	0.036
12	1.58	1.68E+1	10	1.05E+3	1.45E+2	0.138	2.58	1.69	DSO	130	16.8	1.58	0.0357
13	2.51	2.52E+1	10	9.92E+2	1.57E+2	0.158	4.08	2.54	DSO	141	25.2	2.51	0.0352

Data Series Information
Name:			lm3_s3_sw 1
Number of Intervals:			1
Application:			RHEOPLUS/32 V3.62 21006865-33024
Device:			MCR302 SN81338429; FW3.71; Slot(8,-1); Adj(1,0)d
Measuring Date/Time:			16/03/2022; 12:37 PM
Measuring System:			PP08-SN84133; [d=0.65 mm]
Accessories:			TU1=P-PTD200-SN81341740

Calculating Constants:
- Norm. Csr [min/s]:			0.41889996
- Norm. Css [Pa/mNm]:			9,945.692
- Start Delay Time [s]:			7.548
- Substance Density [rho]:			1,000
- Measurement Type:			1
- Axial Compliance [m/N]:			1E-6
- Position [m]:			1E-6

Interval:			1
Number of Data Points:			13

Time Setting:			16 Meas. Pts.
Measuring Profile:
- Strain			Amplitude gamma = 0.01 ... 10 % log; |Slope| = 5 Pt. / dec
			Angular Frequency omega = 10 rad/s

Meas. Pts.	Strain	Shear Stress	Angular Frequency	Storage Modulus	Loss Modulus	Damping Factor	Deflection Angle	Torque	Status	Time	Shear Stress	Strain	Normal Force
	[%]	[Pa]	[rad/s]	[Pa]	[Pa]	[1]	[mrad]	[µNm]	[]	[s]	[Pa]	[%]	[N]
1	0.01	9.83E-2	10	9.8E+2	7.52E+1	0.0767	0.0163	0.00989	DSO	10.2	0.0983	0.01	0.0626
2	0.0158	1.67E-1	10	1.05E+3	6.74E+1	0.0641	0.0258	0.0168	DSO	21.2	0.167	0.0158	0.0623
3	0.0251	2.61E-1	10	1.03E+3	9.52E+1	0.0921	0.0408	0.0262	DSO	32	0.261	0.0251	0.0615
4	0.0398	4.33E-1	10	1.08E+3	9.34E+1	0.0861	0.0647	0.0436	DSO	42.8	0.433	0.0398	0.0605
5	0.0631	6.77E-1	10	1.07E+3	9.17E+1	0.0858	0.103	0.0681	DSO	53.8	0.677	0.0631	0.0602
6	0.1	1.11E0	10	1.1E+3	8.46E+1	0.0767	0.163	0.111	DSO	64.7	1.11	0.1	0.0596
7	0.158	1.78E0	10	1.12E+3	8.09E+1	0.0721	0.258	0.179	DSO	75.5	1.78	0.158	0.0592
8	0.251	2.89E0	10	1.15E+3	8.48E+1	0.074	0.408	0.29	DSO	86.5	2.89	0.251	0.059
9	0.398	4.66E0	10	1.17E+3	9.1E+1	0.0779	0.647	0.469	DSO	97.4	4.66	0.398	0.0586
10	0.631	7.31E0	10	1.15E+3	1.02E+2	0.0885	1.03	0.735	DSO	108	7.31	0.631	0.0583
11	1	1.04E+1	10	1.03E+3	1.27E+2	0.123	1.63	1.05	DSO	119	10.4	1	0.0579
12	1.58	1.6E+1	10	9.99E+2	1.53E+2	0.153	2.58	1.61	DSO	130	16	1.58	0.0579
13	2.51	2.38E+1	10	9.28E+2	1.83E+2	0.197	4.08	2.39	DSO	141	23.8	2.51	0.0575

Data Series Information
Name:			ls5_s1_sw 1
Number of Intervals:			1
Application:			RHEOPLUS/32 V3.62 21006865-33024
Device:			MCR302 SN81338429; FW3.71; Slot(8,-1); Adj(2,0)d
Measuring Date/Time:			16/03/2022; 14:08 PM
Measuring System:			PP08-SN84133; [d=0.94 mm]
Accessories:			TU1=P-PTD200-SN81341740

Calculating Constants:
- Norm. Csr [min/s]:			0.41889996
- Norm. Css [Pa/mNm]:			9,945.692
- Start Delay Time [s]:			8.055
- Substance Density [rho]:			1,000
- Measurement Type:			1
- Axial Compliance [m/N]:			1E-6
- Position [m]:			1E-6

Interval:			1
Number of Data Points:			7

Time Setting:			16 Meas. Pts.
Measuring Profile:
- Strain			Amplitude gamma = 0.01 ... 10 % log; |Slope| = 5 Pt. / dec
			Angular Frequency omega = 10 rad/s

Meas. Pts.	Strain	Shear Stress	Angular Frequency	Storage Modulus	Loss Modulus	Damping Factor	Deflection Angle	Torque	Status	Time	Shear Stress	Strain	Normal Force
	[%]	[Pa]	[rad/s]	[Pa]	[Pa]	[1]	[mrad]	[µNm]	[]	[s]	[Pa]	[%]	[N]
1	0.01	4.2E-2	10	4.2E+2	0	0	0.0235	0.00423	ME-,taD	10.2	0.042	0.01	0.0577
2	0.0158	3.52E-2	10	2.22E+2	0	0	0.0372	0.00354	ME-,taD	21.2	0.0352	0.0158	0.0575
3	0.0251	5.72E-2	10	2.28E+2	0	0	0.059	0.00575	ME-,taD	32.1	0.0572	0.0251	0.0568
4	0.0398	8.95E-2	10	2.25E+2	0	0	0.0936	0.009	ME-,taD	42.9	0.0895	0.0398	0.0568
5	0.0631	1.31E-1	10	2.07E+2	0	0	0.148	0.0131	ME-,taD	53.9	0.131	0.0631	0.0565
6	0.1	1.62E-1	10	1.62E+2	0	0	0.235	0.0163	ME-,taD	64.7	0.162	0.1	0.0563
7	0.158	1.86E-1	10	0	1.17E+2	1,000,000,000,000,000,000,000,000,000,000	0.372	0.0187	ME-,taD	75.5	0.186	0.158	0.0561

Data Series Information
Name:			ls5_s1_sw_repeat 1
Number of Intervals:			1
Application:			RHEOPLUS/32 V3.62 21006865-33024
Device:			MCR302 SN81338429; FW3.71; Slot(8,-1); Adj(2,0)d
Measuring Date/Time:			16/03/2022; 14:22 PM
Measuring System:			PP08-SN84133; [d=0.95 mm]
Accessories:			TU1=P-PTD200-SN81341740

Calculating Constants:
- Norm. Csr [min/s]:			0.41889996
- Norm. Css [Pa/mNm]:			9,945.692
- Start Delay Time [s]:			7.683
- Substance Density [rho]:			1,000
- Measurement Type:			1
- Axial Compliance [m/N]:			1E-6
- Position [m]:			1E-6

Interval:			1
Number of Data Points:			11

Time Setting:			16 Meas. Pts.
Measuring Profile:
- Strain			Amplitude gamma = 0.01 ... 10 % log; |Slope| = 5 Pt. / dec
			Angular Frequency omega = 10 rad/s

Meas. Pts.	Strain	Shear Stress	Angular Frequency	Storage Modulus	Loss Modulus	Damping Factor	Deflection Angle	Torque	Status	Time	Shear Stress	Strain	Normal Force
	[%]	[Pa]	[rad/s]	[Pa]	[Pa]	[1]	[mrad]	[µNm]	[]	[s]	[Pa]	[%]	[N]
1	0.01	4.69E-2	10	4.62E+2	7.68E+1	0.166	0.0237	0.00471	DSO	10.2	0.0469	0.01	0.0569
2	0.0158	6.69E-2	10	4.17E+2	6.46E+1	0.155	0.0376	0.00672	DSO	21.2	0.0669	0.0158	0.0568
3	0.0251	1.09E-1	10	4.24E+2	9.16E+1	0.216	0.0597	0.011	DSO	32.1	0.109	0.0251	0.0571
4	0.0398	1.85E-1	10	4.53E+2	1.07E+2	0.237	0.0946	0.0186	DSO	42.9	0.185	0.0398	0.0565
5	0.0631	3.11E-1	10	4.83E+2	1.01E+2	0.209	0.15	0.0313	DSO	53.9	0.311	0.0631	0.0565
6	0.1	5.11E-1	10	5E+2	1.02E+2	0.204	0.237	0.0514	DSO	64.7	0.511	0.1	0.0559
7	0.158	7.95E-1	10	4.9E+2	1.08E+2	0.221	0.376	0.0799	DSO	75.5	0.795	0.158	0.0561
8	0.251	1.18E0	10	4.54E+2	1.17E+2	0.259	0.597	0.118	DSO	86.5	1.18	0.251	0.0558
9	0.398	1.76E0	10	4.23E+2	1.32E+2	0.313	0.945	0.177	DSO	97.4	1.76	0.398	0.0558
10	0.631	2.18E0	10	3.16E+2	1.42E+2	0.45	1.5	0.22	DSO	108	2.18	0.631	0.0553
11	1	3.18E0	10	2.8E+2	1.51E+2	0.539	2.38	0.319	DSO	119	3.18	1	0.0553

Data Series Information
Name:			ls5_s2_sw 1
Number of Intervals:			1
Application:			RHEOPLUS/32 V3.62 21006865-33024
Device:			MCR302 SN81338429; FW3.71; Slot(8,-1); Adj(2,0)d
Measuring Date/Time:			16/03/2022; 15:09 PM
Measuring System:			PP08-SN84133; [d=1 mm]
Accessories:			TU1=P-PTD200-SN81341740

Calculating Constants:
- Norm. Csr [min/s]:			0.41889996
- Norm. Css [Pa/mNm]:			9,945.692
- Start Delay Time [s]:			7.787
- Substance Density [rho]:			1,000
- Measurement Type:			1
- Axial Compliance [m/N]:			1E-6
- Position [m]:			1E-6

Interval:			1
Number of Data Points:			10

Time Setting:			16 Meas. Pts.
Measuring Profile:
- Strain			Amplitude gamma = 0.01 ... 10 % log; |Slope| = 5 Pt. / dec
			Angular Frequency omega = 10 rad/s

Meas. Pts.	Strain	Shear Stress	Angular Frequency	Storage Modulus	Loss Modulus	Damping Factor	Deflection Angle	Torque	Status	Time	Shear Stress	Strain	Normal Force
	[%]	[Pa]	[rad/s]	[Pa]	[Pa]	[1]	[mrad]	[µNm]	[]	[s]	[Pa]	[%]	[N]
1	0.01	4.6E-2	10	4.57E+2	5.61E+1	0.123	0.025	0.00463	DSO	10.1	0.046	0.01	0.123
2	0.0159	7.21E-2	10	4.52E+2	4.52E+1	0.0999	0.0396	0.00725	DSO	21.1	0.0721	0.0159	0.123
3	0.0251	1.23E-1	10	4.71E+2	1.32E+2	0.28	0.0628	0.0123	DSO	32	0.123	0.0251	0.123
4	0.0398	2.2E-1	10	5.32E+2	1.44E+2	0.271	0.0995	0.0221	DSO	42.8	0.22	0.0398	0.123
5	0.0631	3.33E-1	10	5.12E+2	1.26E+2	0.246	0.158	0.0334	DSO	53.8	0.333	0.0631	0.122
6	0.1	5.16E-1	10	5.02E+2	1.19E+2	0.236	0.25	0.0519	DSO	64.7	0.516	0.1	0.122
7	0.158	7.87E-1	10	4.8E+2	1.26E+2	0.262	0.396	0.0791	DSO	75.5	0.787	0.158	0.122
8	0.251	1.23E0	10	4.71E+2	1.4E+2	0.297	0.628	0.124	DSO	86.5	1.23	0.251	0.122
9	0.398	2.23E0	10	5.42E+2	1.47E+2	0.272	0.995	0.225	DSO	97.4	2.23	0.398	0.122
10	0.631	4.65E0	10	7.2E+2	1.61E+2	0.223	1.58	0.468	DSO	108	4.65	0.631	0.121

Data Series Information
Name:			ls5_s3_sw 1
Number of Intervals:			1
Application:			RHEOPLUS/32 V3.62 21006865-33024
Device:			MCR302 SN81338429; FW3.71; Slot(8,-1); Adj(2,0)d
Measuring Date/Time:			16/03/2022; 15:38 PM
Measuring System:			PP08-SN84133; [d=1 mm]
Accessories:			TU1=P-PTD200-SN81341740

Calculating Constants:
- Norm. Csr [min/s]:			0.41889996
- Norm. Css [Pa/mNm]:			9,945.692
- Start Delay Time [s]:			7.119
- Substance Density [rho]:			1,000
- Measurement Type:			1
- Axial Compliance [m/N]:			1E-6
- Position [m]:			1E-6

Interval:			1
Number of Data Points:			10

Time Setting:			16 Meas. Pts.
Measuring Profile:
- Strain			Amplitude gamma = 0.01 ... 10 % log; |Slope| = 5 Pt. / dec
			Angular Frequency omega = 10 rad/s

Meas. Pts.	Strain	Shear Stress	Angular Frequency	Storage Modulus	Loss Modulus	Damping Factor	Deflection Angle	Torque	Status	Time	Shear Stress	Strain	Normal Force
	[%]	[Pa]	[rad/s]	[Pa]	[Pa]	[1]	[mrad]	[µNm]	[]	[s]	[Pa]	[%]	[N]
1	0.01	1.19E-2	10	1.19E+2	4.8E0	0.0403	0.025	0.0012	M- ,MV-	10.2	0.0119	0.01	0.0722
2	0.0159	3.52E-2	10	1.9E+2	1.15E+2	0.604	0.0396	0.00354	DSO	21.2	0.0352	0.0159	0.0721
3	0.0251	4.66E-2	10	1.51E+2	1.08E+2	0.712	0.0628	0.00469	DSO	32	0.0466	0.0251	0.0715
4	0.0398	1.06E-1	10	2.38E+2	1.21E+2	0.51	0.0995	0.0107	DSO	42.8	0.106	0.0398	0.0719
5	0.0631	1.91E-1	10	2.82E+2	1.1E+2	0.392	0.158	0.0192	DSO	53.8	0.191	0.0631	0.0713
6	0.1	3.03E-1	10	2.78E+2	1.19E+2	0.428	0.25	0.0304	DSO	64.7	0.303	0.1	0.0707
7	0.158	4.85E-1	10	2.76E+2	1.32E+2	0.477	0.396	0.0488	DSO	75.5	0.485	0.158	0.0709
8	0.251	6.94E-1	10	2.39E+2	1.38E+2	0.575	0.628	0.0698	DSO	86.5	0.694	0.251	0.0707
9	0.398	1.34E0	10	3.02E+2	1.51E+2	0.499	0.995	0.135	DSO	97.4	1.34	0.398	0.0708
10	0.631	3.22E0	10	4.83E+2	1.67E+2	0.345	1.58	0.324	DSO	108	3.22	0.631	0.0704

Data Series Information
Name:			ls5_s3_sw_higherforce 1
Number of Intervals:			1
Application:			RHEOPLUS/32 V3.62 21006865-33024
Device:			MCR302 SN81338429; FW3.71; Slot(8,-1); Adj(2,0)d
Measuring Date/Time:			16/03/2022; 15:41 PM
Measuring System:			PP08-SN84133; [d=0.98 mm]
Accessories:			TU1=P-PTD200-SN81341740

Calculating Constants:
- Norm. Csr [min/s]:			0.41889996
- Norm. Css [Pa/mNm]:			9,945.692
- Start Delay Time [s]:			7.195
- Substance Density [rho]:			1,000
- Measurement Type:			1
- Axial Compliance [m/N]:			1E-6
- Position [m]:			1E-6

Interval:			1
Number of Data Points:			10

Time Setting:			16 Meas. Pts.
Measuring Profile:
- Strain			Amplitude gamma = 0.01 ... 10 % log; |Slope| = 5 Pt. / dec
			Angular Frequency omega = 10 rad/s

Meas. Pts.	Strain	Shear Stress	Angular Frequency	Storage Modulus	Loss Modulus	Damping Factor	Deflection Angle	Torque	Status	Time	Shear Stress	Strain	Normal Force
	[%]	[Pa]	[rad/s]	[Pa]	[Pa]	[1]	[mrad]	[µNm]	[]	[s]	[Pa]	[%]	[N]
1	0.00999	9.54E-2	10	3.66E+2	8.81E+2	2.41	0.0245	0.00959	DSO	10.2	0.0954	0.00999	0.0961
2	0.0158	7.94E-2	10	3.03E+2	3.99E+2	1.32	0.0388	0.00798	DSO	21.2	0.0794	0.0158	0.0957
3	0.0251	1.16E-1	10	4.28E+2	1.76E+2	0.41	0.0616	0.0117	DSO	32.1	0.116	0.0251	0.0958
4	0.0398	1.27E-1	10	2.9E+2	1.35E+2	0.466	0.0975	0.0128	DSO	42.9	0.127	0.0398	0.0955
5	0.0631	2.04E-1	10	2.65E+2	1.86E+2	0.7	0.155	0.0206	DSO	53.9	0.204	0.0631	0.0951
6	0.1	3.6E-1	10	3.35E+2	1.31E+2	0.392	0.245	0.0362	DSO	64.7	0.36	0.1	0.0951
7	0.158	6.73E-1	10	3.96E+2	1.54E+2	0.389	0.388	0.0677	DSO	75.5	0.673	0.158	0.0946
8	0.251	1.2E0	10	4.53E+2	1.46E+2	0.323	0.615	0.12	DSO	86.5	1.2	0.251	0.0946
9	0.398	2.29E0	10	5.53E+2	1.53E+2	0.277	0.975	0.23	DSO	97.4	2.29	0.398	0.0944
10	0.631	4.8E0	10	7.39E+2	1.78E+2	0.241	1.55	0.482	DSO	108	4.8	0.631	0.0942

Data Series Information
Name:			CS_s1_sw_pp15 1
Number of Intervals:			1
Application:			RHEOPLUS/32 V3.62 21006865-33024
Device:			MCR302 SN81338429; FW3.71; Slot(7,-1)
Measuring Date/Time:			16/03/2022; 17:49 PM
Measuring System:			PP15-SN58414; [d=0.88 mm]
Accessories:			TU1=P-PTD200-SN81341740

Calculating Constants:
- Norm. Csr [min/s]:			0.78459182
- Norm. Css [Pa/mNm]:			1,513.682
- Start Delay Time [s]:			7.794
- Substance Density [rho]:			1,000
- Measurement Type:			1
- Axial Compliance [m/N]:			1E-6
- Position [m]:			1E-6

Interval:			1
Number of Data Points:			16

Time Setting:			16 Meas. Pts.
Measuring Profile:
- Strain			Amplitude gamma = 0.01 ... 10 % log; |Slope| = 5 Pt. / dec
			Angular Frequency omega = 10 rad/s

Meas. Pts.	Strain	Shear Stress	Angular Frequency	Storage Modulus	Loss Modulus	Damping Factor	Deflection Angle	Torque	Status	Time	Shear Stress	Strain	Normal Force
	[%]	[Pa]	[rad/s]	[Pa]	[Pa]	[1]	[mrad]	[µNm]	[]	[s]	[Pa]	[%]	[N]
1	0.01	1.48E-3	10	7.5E0	1.28E+1	1.7	0.0117	0.000979	M- ,DSO	10.1	0.00148	0.01	0.072
2	0.0159	2.52E-3	10	1.21E+1	1.04E+1	0.862	0.0186	0.00167	M- ,DSO	21.1	0.00252	0.0159	0.0719
3	0.0251	7.26E-3	10	2.81E+1	6.79E0	0.242	0.0295	0.0048	DSO	32.1	0.00726	0.0251	0.0722
4	0.0398	1.24E-2	10	3.05E+1	6.35E0	0.208	0.0468	0.0082	DSO	42.9	0.0124	0.0398	0.072
5	0.0631	1.65E-2	10	2.55E+1	5.67E0	0.222	0.0741	0.0109	DSO	53.8	0.0165	0.0631	0.0718
6	0.1	2.56E-2	10	2.54E+1	2.69E0	0.106	0.117	0.0169	DSO	64.7	0.0256	0.1	0.0716
7	0.158	3.66E-2	10	2.27E+1	4.24E0	0.187	0.186	0.0242	DSO	75.5	0.0366	0.158	0.0716
8	0.251	5.75E-2	10	2.23E+1	5.02E0	0.225	0.295	0.038	DSO	86.5	0.0575	0.251	0.071
9	0.398	9.15E-2	10	2.23E+1	5.55E0	0.249	0.468	0.0605	DSO	97.4	0.0915	0.398	0.0708
10	0.631	1.53E-1	10	2.37E+1	5.34E0	0.226	0.741	0.101	DSO	108	0.153	0.631	0.0711
11	1	2.53E-1	10	2.47E+1	5.51E0	0.223	1.17	0.167	DSO	119	0.253	1	0.0708
12	1.58	3.91E-1	10	2.39E+1	5.82E0	0.243	1.86	0.258	DSO	130	0.391	1.58	0.0705
13	2.51	5.98E-1	10	2.3E+1	6.24E0	0.272	2.95	0.395	DSO	141	0.598	2.51	0.0706
14	3.98	9.31E-1	10	2.25E+1	6.49E0	0.289	4.68	0.615	DSO	152	0.931	3.98	0.0703
15	6.31	1.43E0	10	2.16E+1	6.77E0	0.313	7.41	0.943	DSO	163	1.43	6.31	0.0701
16	10	2.13E0	10	2.03E+1	6.32E0	0.311	11.7	1.41	DSO	174	2.13	10	0.0699

Data Series Information
Name:			CS_s2_sw_pp15_brk 1
Number of Intervals:			1
Application:			RHEOPLUS/32 V3.62 21006865-33024
Device:			MCR302 SN81338429; FW3.71; Slot(7,-1)
Measuring Date/Time:			16/03/2022; 18:28 PM
Measuring System:			PP15-SN58414; [d=0.5 mm]
Accessories:			TU1=P-PTD200-SN81341740

Calculating Constants:
- Norm. Csr [min/s]:			0.78459182
- Norm. Css [Pa/mNm]:			1,513.682
- Start Delay Time [s]:			8.21
- Substance Density [rho]:			1,000
- Measurement Type:			1
- Axial Compliance [m/N]:			1E-6
- Position [m]:			1E-6

Interval:			1
Number of Data Points:			16

Time Setting:			16 Meas. Pts.
Measuring Profile:
- Strain			Amplitude gamma = 0.01 ... 10 % log; |Slope| = 5 Pt. / dec
			Angular Frequency omega = 10 rad/s

Meas. Pts.	Strain	Shear Stress	Angular Frequency	Storage Modulus	Loss Modulus	Damping Factor	Deflection Angle	Torque	Status	Time	Shear Stress	Strain	Normal Force
	[%]	[Pa]	[rad/s]	[Pa]	[Pa]	[1]	[mrad]	[µNm]	[]	[s]	[Pa]	[%]	[N]
1	0.01	5.21E-3	10	5.21E+1	6.52E-1	0.0125	0.00667	0.00344	MV-,DSO	10.2	0.00521	0.01	0.143
2	0.0159	3.91E-3	10	2.34E+1	7.79E0	0.333	0.0106	0.00258	DSO	21.2	0.00391	0.0159	0.142
3	0.0251	7.08E-3	10	2.73E+1	6.95E0	0.254	0.0168	0.00468	DSO	32	0.00708	0.0251	0.14
4	0.0398	1.14E-2	10	2.85E+1	2.7E0	0.0947	0.0266	0.00753	DSO	42.9	0.0114	0.0398	0.139
5	0.0631	2E-2	10	3.14E+1	3.91E0	0.125	0.0421	0.0132	DSO	53.8	0.02	0.0631	0.139
6	0.1	3.28E-2	10	3.26E+1	3.52E0	0.108	0.0667	0.0216	DSO	64.7	0.0328	0.1	0.138
7	0.158	5.48E-2	10	3.45E+1	2.96E0	0.0859	0.106	0.0362	DSO	75.5	0.0548	0.158	0.138
8	0.251	8.89E-2	10	3.53E+1	3.26E0	0.0924	0.168	0.0588	DSO	86.5	0.0889	0.251	0.138
9	0.398	1.29E-1	10	3.24E+1	3.02E0	0.0933	0.266	0.0855	DSO	97.4	0.129	0.398	0.138
10	0.631	1.79E-1	10	2.82E+1	3.08E0	0.109	0.421	0.118	DSO	108	0.179	0.631	0.137
11	1	2.19E-1	10	2.16E+1	3.3E0	0.152	0.667	0.145	DSO	119	0.219	1	0.136
12	1.58	2.82E-1	10	1.74E+1	3.55E0	0.204	1.06	0.186	DSO	130	0.282	1.58	0.137
13	2.51	4.58E-1	10	1.79E+1	3.61E0	0.202	1.68	0.303	DSO	141	0.458	2.51	0.136
14	3.98	7.07E-1	10	1.73E+1	3.86E0	0.223	2.66	0.467	DSO	152	0.707	3.98	0.136
15	6.31	1.12E0	10	1.72E+1	4.11E0	0.238	4.21	0.738	DSO	163	1.12	6.31	0.136
16	10	1.7E0	10	1.64E+1	4.48E0	0.272	6.67	1.13	DSO	174	1.7	10	0.135

Data Series Information
Name:			ls1_s1_sw_pp15 1
Number of Intervals:			1
Application:			RHEOPLUS/32 V3.62 21006865-33024
Device:			MCR302 SN81338429; FW3.71; Slot(7,-1)
Measuring Date/Time:			16/03/2022; 19:10 PM
Measuring System:			PP15-SN58414; [d=0.6 mm]
Accessories:			TU1=P-PTD200-SN81341740

Calculating Constants:
- Norm. Csr [min/s]:			0.78459182
- Norm. Css [Pa/mNm]:			1,513.682
- Start Delay Time [s]:			7.33
- Substance Density [rho]:			1,000
- Measurement Type:			1
- Axial Compliance [m/N]:			1E-6
- Position [m]:			1E-6

Interval:			1
Number of Data Points:			13

Time Setting:			16 Meas. Pts.
Measuring Profile:
- Strain			Amplitude gamma = 0.01 ... 10 % log; |Slope| = 5 Pt. / dec
			Angular Frequency omega = 10 rad/s

Meas. Pts.	Strain	Shear Stress	Angular Frequency	Storage Modulus	Loss Modulus	Damping Factor	Deflection Angle	Torque	Status	Time	Shear Stress	Strain	Normal Force
	[%]	[Pa]	[rad/s]	[Pa]	[Pa]	[1]	[mrad]	[µNm]	[]	[s]	[Pa]	[%]	[N]
1	0.01	2.99E-3	10	2.95E+1	4.76E0	0.162	0.00801	0.00197	M- ,DSO	10.2	0.00299	0.01	0.0443
2	0.0158	7.29E-3	10	4.53E+1	7.95E0	0.176	0.0127	0.00482	DSO	21.1	0.00729	0.0158	0.0444
3	0.0251	1.09E-2	10	4.34E+1	4.77E-2	0.0011	0.0201	0.00721	MV-,DSO	32	0.0109	0.0251	0.0444
4	0.0398	1.77E-2	10	4.4E+1	6E0	0.136	0.0319	0.0117	DSO	42.8	0.0177	0.0398	0.0444
5	0.0631	3.09E-2	10	4.88E+1	4.06E0	0.0833	0.0505	0.0204	DSO	53.8	0.0309	0.0631	0.0439
6	0.1	4.84E-2	10	4.84E+1	2.58E0	0.0533	0.0801	0.032	DSO	64.7	0.0484	0.1	0.0434
7	0.158	7.66E-2	10	4.83E+1	2.5E0	0.0517	0.127	0.0506	DSO	75.5	0.0766	0.158	0.0434
8	0.251	1.21E-1	10	4.81E+1	2.91E0	0.0605	0.201	0.0799	DSO	86.5	0.121	0.251	0.0436
9	0.398	1.74E-1	10	4.37E+1	2.39E0	0.0546	0.319	0.115	DSO	97.4	0.174	0.398	0.0439
10	0.631	2.3E-1	10	3.64E+1	2.56E0	0.0704	0.505	0.152	DSO	108	0.23	0.631	0.0435
11	1	2.73E-1	10	2.72E+1	2.59E0	0.0953	0.801	0.18	DSO	119	0.273	1	0.0442
12	1.58	3.76E-1	10	2.36E+1	2.71E0	0.115	1.27	0.248	DSO	130	0.376	1.58	0.0432
13	2.51	5.5E-1	10	2.17E+1	2.76E0	0.127	2.01	0.363	DSO	141	0.55	2.51	0.0436

Data Series Information
Name:			ls1_s2_sw_pp15 1
Number of Intervals:			1
Application:			RHEOPLUS/32 V3.62 21006865-33024
Device:			MCR302 SN81338429; FW3.71; Slot(7,-1)
Measuring Date/Time:			16/03/2022; 19:48 PM
Measuring System:			PP15-SN58414; [d=0.5 mm]
Accessories:			TU1=P-PTD200-SN81341740

Calculating Constants:
- Norm. Csr [min/s]:			0.78459182
- Norm. Css [Pa/mNm]:			1,513.682
- Start Delay Time [s]:			7.12
- Substance Density [rho]:			1,000
- Measurement Type:			1
- Axial Compliance [m/N]:			1E-6
- Position [m]:			1E-6

Interval:			1
Number of Data Points:			16

Time Setting:			16 Meas. Pts.
Measuring Profile:
- Strain			Amplitude gamma = 0.01 ... 10 % log; |Slope| = 5 Pt. / dec
			Angular Frequency omega = 10 rad/s

Meas. Pts.	Strain	Shear Stress	Angular Frequency	Storage Modulus	Loss Modulus	Damping Factor	Deflection Angle	Torque	Status	Time	Shear Stress	Strain	Normal Force
	[%]	[Pa]	[rad/s]	[Pa]	[Pa]	[1]	[mrad]	[µNm]	[]	[s]	[Pa]	[%]	[N]
1	0.01	2.28E-3	10	2.21E+1	5.86E0	0.266	0.00667	0.00151	M- ,DSO	10.2	0.00228	0.01	0.0486
2	0.0158	2.72E-3	10	1.46E+1	9.03E0	0.619	0.0106	0.00179	M- ,MV-	21.1	0.00272	0.0158	0.0484
3	0.0251	6.24E-3	10	2.48E+1	1.55E0	0.0626	0.0168	0.00412	DSO	32	0.00624	0.0251	0.048
4	0.0398	1.15E-2	10	2.88E+1	2.4E0	0.0832	0.0266	0.00761	DSO	42.8	0.0115	0.0398	0.0475
5	0.0631	2.05E-2	10	3.23E+1	3.8E0	0.117	0.0421	0.0136	DSO	53.9	0.0205	0.0631	0.0472
6	0.1	3.21E-2	10	3.19E+1	4.24E0	0.133	0.0667	0.0212	DSO	64.7	0.0321	0.1	0.0471
7	0.158	5.31E-2	10	3.33E+1	3.94E0	0.119	0.106	0.0351	DSO	75.5	0.0531	0.158	0.0473
8	0.251	8.01E-2	10	3.16E+1	4.19E0	0.133	0.168	0.0529	DSO	86.5	0.0801	0.251	0.0471
9	0.398	1.31E-1	10	3.25E+1	4.54E0	0.14	0.266	0.0863	DSO	97.4	0.131	0.398	0.0466
10	0.631	2.24E-1	10	3.53E+1	4.21E0	0.119	0.421	0.148	DSO	108	0.224	0.631	0.0463
11	1	3.74E-1	10	3.72E+1	3.85E0	0.103	0.667	0.247	DSO	119	0.374	1	0.0463
12	1.58	5.89E-1	10	3.69E+1	4.43E0	0.12	1.06	0.389	DSO	130	0.589	1.58	0.0461
13	2.51	9.06E-1	10	3.58E+1	4.53E0	0.127	1.68	0.599	DSO	141	0.906	2.51	0.0466
14	3.98	1.42E0	10	3.53E+1	5.08E0	0.144	2.66	0.938	DSO	152	1.42	3.98	0.0461
15	6.31	2.2E0	10	3.43E+1	6.08E0	0.177	4.21	1.45	DSO	163	2.2	6.31	0.0459
16	10	3.33E0	10	3.25E+1	7.46E0	0.23	6.67	2.2	DSO	174	3.33	10	0.0457

Data Series Information
Name:			ls1_s3_sw_pp15 1
Number of Intervals:			1
Application:			RHEOPLUS/32 V3.62 21006865-33024
Device:			MCR302 SN81338429; FW3.71; Slot(7,-1)
Measuring Date/Time:			16/03/2022; 20:19 PM
Measuring System:			PP15-SN58414; [d=0.65 mm]
Accessories:			TU1=P-PTD200-SN81341740

Calculating Constants:
- Norm. Csr [min/s]:			0.78459182
- Norm. Css [Pa/mNm]:			1,513.682
- Start Delay Time [s]:			7.68
- Substance Density [rho]:			1,000
- Measurement Type:			1
- Axial Compliance [m/N]:			1E-6
- Position [m]:			1E-6

Interval:			1
Number of Data Points:			16

Time Setting:			16 Meas. Pts.
Measuring Profile:
- Strain			Amplitude gamma = 0.01 ... 10 % log; |Slope| = 5 Pt. / dec
			Angular Frequency omega = 10 rad/s

Meas. Pts.	Strain	Shear Stress	Angular Frequency	Storage Modulus	Loss Modulus	Damping Factor	Deflection Angle	Torque	Status	Time	Shear Stress	Strain	Normal Force
	[%]	[Pa]	[rad/s]	[Pa]	[Pa]	[1]	[mrad]	[µNm]	[]	[s]	[Pa]	[%]	[N]
1	0.01	1.63E-3	10	0	1.63E+1	1,000,000,000,000,000,000,000,000,000,000	0.00868	0.00107	M- ,ME-	10.2	0.00163	0.01	0.079
2	0.0158	5.19E-3	10	3.25E+1	3.88E0	0.119	0.0137	0.00343	DSO	21.1	0.00519	0.0158	0.079
3	0.0251	9.36E-3	10	3.65E+1	7.36E0	0.201	0.0218	0.00618	DSO	32	0.00936	0.0251	0.0787
4	0.0398	9.84E-3	10	2.45E+1	3.4E0	0.139	0.0345	0.0065	DSO	42.8	0.00984	0.0398	0.0786
5	0.0631	2.12E-2	10	3.3E+1	6.65E0	0.202	0.0548	0.014	DSO	53.8	0.0212	0.0631	0.0779
6	0.1	2.62E-2	10	2.58E+1	4.9E0	0.19	0.0868	0.0173	DSO	64.7	0.0262	0.1	0.0779
7	0.158	4.58E-2	10	2.86E+1	4.35E0	0.152	0.138	0.0303	DSO	75.5	0.0458	0.158	0.0779
8	0.251	7.64E-2	10	3.02E+1	3.68E0	0.122	0.218	0.0505	DSO	86.5	0.0764	0.251	0.0775
9	0.398	1.4E-1	10	3.49E+1	4.62E0	0.132	0.345	0.0925	DSO	97.4	0.14	0.398	0.0766
10	0.631	2.58E-1	10	4.07E+1	4.28E0	0.105	0.547	0.171	DSO	108	0.258	0.631	0.077
11	1	4.84E-1	10	4.82E+1	4.42E0	0.0917	0.868	0.32	DSO	119	0.484	1	0.0765
12	1.58	7.21E-1	10	4.52E+1	4.45E0	0.0983	1.38	0.476	DSO	130	0.721	1.58	0.0763
13	2.51	1.13E0	10	4.49E+1	4.52E0	0.101	2.18	0.749	DSO	141	1.13	2.51	0.0762
14	3.98	1.8E0	10	4.49E+1	4.66E0	0.104	3.45	1.19	DSO	152	1.8	3.98	0.0762
15	6.31	2.76E0	10	4.34E+1	5.44E0	0.125	5.47	1.82	DSO	163	2.76	6.31	0.0761
16	10	4.27E0	10	4.23E+1	5.92E0	0.14	8.68	2.82	DSO	174	4.27	10	0.0757